<mujoco model="g1_29dof_anneal_23dof">

  <compiler angle="radian" meshdir="../meshes"/>

  <statistic extent="2" center="0 0 1"/>

  <!-- <option timestep="0.00166"/> -->

  <default>
    <motor ctrlrange="-10350 10350" ctrllimited="true"/>
    <default class="body">
      <geom type="capsule" condim="1" friction="1.0 0.05 0.05" solimp=".9 .99 .003" solref=".015 1"/>
      <joint type="hinge" damping="0 " stiffness="0" armature=".007" limited="true" solimplimit="0 .99 .01"/>
      <site size=".04" group="3"/>
      <default class="force-torque">
        <site type="box" size=".01 .01 .02" rgba="1 0 0 1" />
      </default>
      <default class="touch">
        <site type="capsule" rgba="0 0 1 .3"/>
      </default>
    </default>
  </default>

  <asset>
    <mesh name="pelvis" file="pelvis.STL"/>
    <mesh name="pelvis_contour_link" file="pelvis_contour_link.STL"/>
    <mesh name="left_hip_pitch_link" file="left_hip_pitch_link.STL"/>
    <mesh name="left_hip_roll_link" file="left_hip_roll_link.STL"/>
    <mesh name="left_hip_yaw_link" file="left_hip_yaw_link.STL"/>
    <mesh name="left_knee_link" file="left_knee_link.STL"/>
    <mesh name="left_ankle_pitch_link" file="left_ankle_pitch_link.STL"/>
    <mesh name="left_ankle_roll_link" file="left_ankle_roll_link.STL"/>
    <mesh name="right_hip_pitch_link" file="right_hip_pitch_link.STL"/>
    <mesh name="right_hip_roll_link" file="right_hip_roll_link.STL"/>
    <mesh name="right_hip_yaw_link" file="right_hip_yaw_link.STL"/>
    <mesh name="right_knee_link" file="right_knee_link.STL"/>
    <mesh name="right_ankle_pitch_link" file="right_ankle_pitch_link.STL"/>
    <mesh name="right_ankle_roll_link" file="right_ankle_roll_link.STL"/>
    <mesh name="waist_yaw_link" file="waist_yaw_link.STL"/>
    <mesh name="waist_roll_link" file="waist_roll_link.STL"/>
    <mesh name="torso_link" file="torso_link.STL"/>
    <mesh name="logo_link" file="logo_link.STL"/>
    <mesh name="head_link" file="head_link.STL"/>
    <mesh name="waist_support_link" file="waist_support_link.STL"/>
    <mesh name="left_shoulder_pitch_link" file="left_shoulder_pitch_link.STL"/>
    <mesh name="left_shoulder_roll_link" file="left_shoulder_roll_link.STL"/>
    <mesh name="left_shoulder_yaw_link" file="left_shoulder_yaw_link.STL"/>
    <mesh name="left_elbow_link" file="left_elbow_link.STL"/>
    <mesh name="left_wrist_roll_link" file="left_wrist_roll_link.STL"/>
    <mesh name="left_wrist_pitch_link" file="left_wrist_pitch_link.STL"/>
    <mesh name="left_wrist_yaw_link" file="left_wrist_yaw_link.STL"/>
    <mesh name="left_rubber_hand" file="left_rubber_hand.STL"/>
    <mesh name="right_shoulder_pitch_link" file="right_shoulder_pitch_link.STL"/>
    <mesh name="right_shoulder_roll_link" file="right_shoulder_roll_link.STL"/>
    <mesh name="right_shoulder_yaw_link" file="right_shoulder_yaw_link.STL"/>
    <mesh name="right_elbow_link" file="right_elbow_link.STL"/>
    <mesh name="right_wrist_roll_link" file="right_wrist_roll_link.STL"/>
    <mesh name="right_wrist_pitch_link" file="right_wrist_pitch_link.STL"/>
    <mesh name="right_wrist_yaw_link" file="right_wrist_yaw_link.STL"/>
    <mesh name="right_rubber_hand" file="right_rubber_hand.STL"/>
  </asset>

  <worldbody>
    <!-- <geom name="floor" type="plane" conaffinity="1" size="100 100 .2" /> -->
    <body name="pelvis" pos="0 0 0.8"  childclass="body">
      <inertial pos="0 0 -0.0760301" quat="1 0 -0.000398273 0" mass="3.814" diaginertia="0.0105549 0.00931478 0.0079185"/>
      <freejoint name="root"/>
      <site name="root" class="force-torque"/>
      <geom type="mesh" contype="0" conaffinity="0" group="1" density="0" rgba="0.2 0.2 0.2 1" mesh="pelvis"/>
      <geom type="mesh" contype="0" conaffinity="0" group="1" density="0" rgba="0.7 0.7 0.7 1" mesh="pelvis_contour_link"/>
      <geom type="mesh" rgba="0.7 0.7 0.7 1" mesh="pelvis_contour_link"/>
      <body name="left_hip_pitch_link" pos="0 0.064452 -0.1027">
        <inertial pos="0.002741 0.047791 -0.02606" quat="0.954862 0.293964 0.0302556 0.030122" mass="1.35" diaginertia="0.00181517 0.00153422 0.00116212"/>
        <joint name="left_hip_pitch_joint" pos="0 0 0" axis="0 1 0" range="-2.5307 2.8798"   armature=".025" />
        <geom type="mesh" contype="0" conaffinity="0" group="1" density="0" rgba="0.2 0.2 0.2 1" mesh="left_hip_pitch_link"/>
        <geom type="mesh" rgba="0.2 0.2 0.2 1" mesh="left_hip_pitch_link"/>
        <body name="left_hip_roll_link" pos="0 0.052 -0.030465" quat="0.996179 0 -0.0873386 0">
          <inertial pos="0.029812 -0.001045 -0.087934" quat="0.977808 -1.97119e-05 0.205576 -0.0403793" mass="1.52" diaginertia="0.00254986 0.00241169 0.00148755"/>
          <joint  name="left_hip_roll_joint" pos="0 0 0" axis="1 0 0" range="-0.5236 2.9671"      armature=".025" />
          <geom type="mesh" contype="0" conaffinity="0" group="1" density="0" rgba="0.7 0.7 0.7 1" mesh="left_hip_roll_link"/>
          <geom type="mesh" rgba="0.7 0.7 0.7 1" mesh="left_hip_roll_link"/>
          <body name="left_hip_yaw_link" pos="0.025001 0 -0.12412">
            <inertial pos="-0.057709 -0.010981 -0.15078" quat="0.600598 0.15832 0.223482 0.751181" mass="1.702" diaginertia="0.00776166 0.00717575 0.00160139"/>
            <joint  name="left_hip_yaw_joint" pos="0 0 0" axis="0 0 1" range="-2.7576 2.7576"      armature=".025" />
            <geom type="mesh" contype="0" conaffinity="0" group="1" density="0" rgba="0.7 0.7 0.7 1" mesh="left_hip_yaw_link"/>
            <geom type="mesh" rgba="0.7 0.7 0.7 1" mesh="left_hip_yaw_link"/>
            <body name="left_knee_link" pos="-0.078273 0.0021489 -0.17734" quat="0.996179 0 0.0873386 0">
              <inertial pos="0.005457 0.003964 -0.12074" quat="0.923418 -0.0327699 0.0158246 0.382067" mass="1.932" diaginertia="0.0113804 0.0112778 0.00146458"/>
              <joint  name="left_knee_joint" pos="0 0 0" axis="0 1 0" range="-0.087267 2.8798"  armature=".025" />
              <geom type="mesh" contype="0" conaffinity="0" group="1" density="0" rgba="0.7 0.7 0.7 1" mesh="left_knee_link"/>
              <!-- <geom type="mesh" rgba="0.7 0.7 0.7 1" mesh="left_knee_link"/> -->
              <body name="left_ankle_pitch_link" pos="0 -9.4445e-05 -0.30001">
                <inertial pos="-0.007269 0 0.011137" quat="0.603053 0.369225 0.369225 0.603053" mass="0.074" diaginertia="1.89e-05 1.40805e-05 6.9195e-06"/>
                <joint  name="left_ankle_pitch_joint" pos="0 0 0" axis="0 1 0" range="-0.87267 0.5236"  armature=".025" />
                <geom type="mesh" contype="0" conaffinity="0" group="1" density="0" rgba="0.7 0.7 0.7 1" mesh="left_ankle_pitch_link"/>
                <geom type="mesh" rgba="0.7 0.7 0.7 1" mesh="left_ankle_pitch_link"/>
                <body name="left_ankle_roll_link" pos="0 0 -0.017558">
                  <inertial pos="0.026505 0 -0.016425" quat="-0.000481092 0.728482 -0.000618967 0.685065" mass="0.608" diaginertia="0.00167218 0.0016161 0.000217621"/>
                  <joint  name="left_ankle_roll_joint" pos="0 0 0" axis="1 0 0" range="-0.2618 0.2618"  armature=".025" />
                  <geom type="mesh" contype="0" conaffinity="0" group="1" density="0" rgba="0.2 0.2 0.2 1" mesh="left_ankle_roll_link"/>
                  <geom type="mesh"  rgba="0.2 0.2 0.2 1" mesh="left_ankle_roll_link"/>
                  <!-- <geom size="0.005" pos="-0.05 0.025 -0.03" rgba="0.2 0.2 0.2 1"/>
                  <geom size="0.005" pos="-0.05 -0.025 -0.03" rgba="0.2 0.2 0.2 1"/>
                  <geom size="0.005" pos="0.12 0.03 -0.03" rgba="0.2 0.2 0.2 1"/>
                  <geom size="0.005" pos="0.12 -0.03 -0.03" rgba="0.2 0.2 0.2 1"/> -->
                </body>
              </body>
            </body>
          </body>
        </body>
      </body>

      <body name="right_hip_pitch_link" pos="0 -0.064452 -0.1027">
        <inertial pos="0.002741 -0.047791 -0.02606" quat="0.954862 -0.293964 0.0302556 -0.030122" mass="1.35" diaginertia="0.00181517 0.00153422 0.00116212"/>
        <joint  name="right_hip_pitch_joint" pos="0 0 0" axis="0 1 0" range="-2.5307 2.8798"      armature=".025" />
        <geom type="mesh" contype="0" conaffinity="0" group="1" density="0" rgba="0.2 0.2 0.2 1" mesh="right_hip_pitch_link"/>
        <geom type="mesh" rgba="0.2 0.2 0.2 1" mesh="right_hip_pitch_link"/>
        <body name="right_hip_roll_link" pos="0 -0.052 -0.030465" quat="0.996179 0 -0.0873386 0">
          <inertial pos="0.029812 0.001045 -0.087934" quat="0.977808 1.97119e-05 0.205576 0.0403793" mass="1.52" diaginertia="0.00254986 0.00241169 0.00148755"/>
          <joint  name="right_hip_roll_joint" pos="0 0 0" axis="1 0 0" range="-2.9671 0.5236"      armature=".025" />
          <geom type="mesh" contype="0" conaffinity="0" group="1" density="0" rgba="0.7 0.7 0.7 1" mesh="right_hip_roll_link"/>
          <geom type="mesh" rgba="0.7 0.7 0.7 1" mesh="right_hip_roll_link"/>
          <body name="right_hip_yaw_link" pos="0.025001 0 -0.12412">
            <inertial pos="-0.057709 0.010981 -0.15078" quat="0.751181 0.223482 0.15832 0.600598" mass="1.702" diaginertia="0.00776166 0.00717575 0.00160139"/>
            <joint  name="right_hip_yaw_joint" pos="0 0 0" axis="0 0 1" range="-2.7576 2.7576"      armature=".025" />
            <geom type="mesh" contype="0" conaffinity="0" group="1" density="0" rgba="0.7 0.7 0.7 1" mesh="right_hip_yaw_link"/>
            <geom type="mesh" rgba="0.7 0.7 0.7 1" mesh="right_hip_yaw_link"/>
            <body name="right_knee_link" pos="-0.078273 -0.0021489 -0.17734" quat="0.996179 0 0.0873386 0">
              <inertial pos="0.005457 -0.003964 -0.12074" quat="0.923439 0.0345276 0.0116333 -0.382012" mass="1.932" diaginertia="0.011374 0.0112843 0.00146452"/>
              <joint  name="right_knee_joint" pos="0 0 0" axis="0 1 0" range="-0.087267 2.8798"     armature=".025" />
              <geom type="mesh" contype="0" conaffinity="0" group="1" density="0" rgba="0.7 0.7 0.7 1" mesh="right_knee_link"/>
              <!-- <geom type="mesh" rgba="0.7 0.7 0.7 1" mesh="right_knee_link"/> -->
              <body name="right_ankle_pitch_link" pos="0 9.4445e-05 -0.30001">
                <inertial pos="-0.007269 0 0.011137" quat="0.603053 0.369225 0.369225 0.603053" mass="0.074" diaginertia="1.89e-05 1.40805e-05 6.9195e-06"/>
                <joint  name="right_ankle_pitch_joint" pos="0 0 0" axis="0 1 0" range="-0.87267 0.5236"  armature=".025" />
                <geom type="mesh" contype="0" conaffinity="0" group="1" density="0" rgba="0.7 0.7 0.7 1" mesh="right_ankle_pitch_link"/>
                <geom type="mesh" rgba="0.7 0.7 0.7 1" mesh="right_ankle_pitch_link"/>
                <body name="right_ankle_roll_link" pos="0 0 -0.017558">
                  <inertial pos="0.026505 0 -0.016425" quat="0.000481092 0.728482 0.000618967 0.685065" mass="0.608" diaginertia="0.00167218 0.0016161 0.000217621"/>
                  <joint  name="right_ankle_roll_joint" pos="0 0 0" axis="1 0 0" range="-0.2618 0.2618"  armature=".025" />
                  <geom type="mesh" contype="0" conaffinity="0" group="1" density="0" rgba="0.2 0.2 0.2 1" mesh="right_ankle_roll_link"/>
                  <geom type="mesh"  rgba="0.2 0.2 0.2 1" mesh="right_ankle_roll_link"/> 
                </body>
              </body>
            </body>
          </body>
        </body>
      </body>
      <body name="waist_yaw_link">
        <inertial pos="0.003964 0 0.018769" quat="-0.0178291 0.628464 0.0282471 0.777121" mass="0.244" diaginertia="0.000158561 0.000124229 9.67669e-05"/>
        <joint  name="waist_yaw_joint" pos="0 0 0" axis="0 0 1" range="-2.618 2.618"       armature=".025" />
        <geom type="mesh" contype="0" conaffinity="0" group="1" density="0" rgba="0.7 0.7 0.7 1" mesh="waist_yaw_link"/>
        <body name="waist_roll_link" pos="-0.0039635 0 0.035">
          <inertial pos="0 -0.000236 0.010111" quat="0.99979 0.020492 0 0" mass="0.047" diaginertia="7.515e-06 6.40206e-06 3.98394e-06"/>
          <joint  name="waist_roll_joint" pos="0 0 0" axis="1 0 0" range="-0.52 0.52"     armature=".025" />
          <geom type="mesh" contype="0" conaffinity="0" group="1" density="0" rgba="0.7 0.7 0.7 1" mesh="waist_roll_link"/>
          <body name="torso_link" pos="0 0 0.019">
            <inertial pos="0.00331658 0.000261533 0.179856" quat="0.999831 0.000376204 0.0179895 -0.00377704" mass="9.598" diaginertia="0.12407 0.111951 0.0325382"/>
            <joint  name="waist_pitch_joint" pos="0 0 0" axis="0 1 0" range="-0.52 0.52"     armature=".025" />
            <geom type="mesh" contype="0" conaffinity="0" group="1" density="0" rgba="0.7 0.7 0.7 1" mesh="torso_link"/>
            <geom type="mesh" rgba="0.7 0.7 0.7 1" mesh="torso_link"/>
            <geom pos="0.0039635 0 -0.054" quat="1 0 0 0" type="mesh" contype="0" conaffinity="0" group="1" density="0" rgba="0.2 0.2 0.2 1" mesh="logo_link"/>
            <geom pos="0.0039635 0 -0.054" quat="1 0 0 0" type="mesh" rgba="0.2 0.2 0.2 1" mesh="logo_link"/>
            <geom pos="0.0039635 0 -0.054" type="mesh" contype="0" conaffinity="0" group="1" density="0" rgba="0.2 0.2 0.2 1" mesh="head_link"/>
            <geom pos="0.0039635 0 -0.054" type="mesh" rgba="0.2 0.2 0.2 1" mesh="head_link"/>
            <geom pos="0.0039635 0 -0.054" quat="1 0 0 0" type="mesh" contype="0" conaffinity="0" group="1" density="0" rgba="0.7 0.7 0.7 1" mesh="waist_support_link"/>
            <geom pos="0.0039635 0 -0.054" quat="1 0 0 0" type="mesh" rgba="0.7 0.7 0.7 1" mesh="waist_support_link"/>
            <site name="imu" size="0.01" pos="-0.03959 -0.00224 0.13792"/>
            <body name="left_shoulder_pitch_link" pos="0.0039563 0.10022 0.23778" quat="0.990264 0.139201 1.38722e-05 -9.86868e-05">
              <inertial pos="0 0.035892 -0.011628" quat="0.654152 0.0130458 -0.326267 0.68225" mass="0.718" diaginertia="0.000465864 0.000432842 0.000406394"/>
              <joint  name="left_shoulder_pitch_joint" pos="0 0 0" axis="0 1 0" range="-3.0892 2.6704"          armature=".025" />
              <geom type="mesh" contype="0" conaffinity="0" group="1" density="0" rgba="0.7 0.7 0.7 1" mesh="left_shoulder_pitch_link"/>
              <geom size="0.03 0.025" pos="0 0.04 -0.01" quat="0.707107 0 0.707107 0" type="cylinder" rgba="0.7 0.7 0.7 1"/>
              <body name="left_shoulder_roll_link" pos="0 0.038 -0.013831" quat="0.990268 -0.139172 0 0">
                <inertial pos="-0.000227 0.00727 -0.063243" quat="0.701256 -0.0196223 -0.00710317 0.712604" mass="0.643" diaginertia="0.000691311 0.000618011 0.000388977"/>
                <joint  name="left_shoulder_roll_joint" pos="0 0 0" axis="1 0 0" range="-1.5882 2.2515"        armature=".025" />
                <geom type="mesh" contype="0" conaffinity="0" group="1" density="0" rgba="0.7 0.7 0.7 1" mesh="left_shoulder_roll_link"/>
                <geom size="0.03 0.015" pos="-0.004 0.006 -0.053" type="cylinder" rgba="0.7 0.7 0.7 1"/>
                <body name="left_shoulder_yaw_link" pos="0 0.00624 -0.1032">
                  <inertial pos="0.010773 -0.002949 -0.072009" quat="0.716879 -0.0964829 -0.0679942 0.687134" mass="0.734" diaginertia="0.00106187 0.00103217 0.000400661"/>
                  <joint  name="left_shoulder_yaw_joint" pos="0 0 0" axis="0 0 1" range="-2.618 2.618"         armature=".025" />
                  <geom type="mesh" contype="0" conaffinity="0" group="1" density="0" rgba="0.7 0.7 0.7 1" mesh="left_shoulder_yaw_link"/>
                  <geom type="mesh" rgba="0.7 0.7 0.7 1" mesh="left_shoulder_yaw_link"/>
                  <body name="left_elbow_link" pos="0.015783 0 -0.080518">
                    <inertial pos="0.134675 0.00265598 -0.0101165" quat="0.514554 0.498203 0.50107 0.485754" mass="1.42407" diaginertia="0.00848486 0.00842107 0.000653284"/>
                    <joint    name="left_elbow_joint" pos="0 0 0" axis="0 1 0" range="-1.0472 2.0944"        armature=".025" />
                    <geom type="mesh" contype="0" conaffinity="0" group="1" density="0" rgba="0.7 0.7 0.7 1" mesh="left_elbow_link"/>
                    <geom type="mesh" rgba="0.7 0.7 0.7 1" mesh="left_elbow_link"/>
                    <geom pos="0.1 0.00188791 -0.01" type="mesh" contype="0" conaffinity="0" group="1" density="0" rgba="0.7 0.7 0.7 1" mesh="left_wrist_roll_link"/>
                    <geom pos="0.1 0.00188791 -0.01" type="mesh" rgba="0.7 0.7 0.7 1" mesh="left_wrist_roll_link"/>
                    <geom pos="0.138 0.00188791 -0.01" type="mesh" contype="0" conaffinity="0" group="1" density="0" rgba="0.7 0.7 0.7 1" mesh="left_wrist_pitch_link"/>
                    <geom pos="0.138 0.00188791 -0.01" type="mesh" rgba="0.7 0.7 0.7 1" mesh="left_wrist_pitch_link"/>
                    <geom pos="0.184 0.00188791 -0.01" type="mesh" contype="0" conaffinity="0" group="1" density="0" rgba="0.7 0.7 0.7 1" mesh="left_wrist_yaw_link"/>
                    <geom pos="0.184 0.00188791 -0.01" type="mesh" rgba="0.7 0.7 0.7 1" mesh="left_wrist_yaw_link"/>
                    <geom pos="0.2255 0.00488791 -0.01" type="mesh" contype="0" conaffinity="0" group="1" density="0" rgba="0.7 0.7 0.7 1" mesh="left_rubber_hand"/>
                    <geom pos="0.2255 0.00488791 -0.01" type="mesh" rgba="0.7 0.7 0.7 1" mesh="left_rubber_hand"/>
                    <body name="left_hand_link" pos="0.25 0 0">
                      <!-- <inertial pos="0.0536131 0.00295905 0.00215413" quat="0.464597 0.435405 0.552264 0.538123" mass="0.17" diaginertia="0.000288486 0.000218824 9.39911e-05"/> -->
                      <geom type="sphere"  size="0.035" contype="0" conaffinity="0" group="1" density="0" rgba="0 0 0.7 1"/>
                    </body> 
                  </body>
                </body>
              </body>
            </body>
            <body name="right_shoulder_pitch_link" pos="0.0039563 -0.10021 0.23778" quat="0.990264 -0.139201 1.38722e-05 9.86868e-05">
              <inertial pos="0 -0.035892 -0.011628" quat="0.68225 -0.326267 0.0130458 0.654152" mass="0.718" diaginertia="0.000465864 0.000432842 0.000406394"/>
              <joint  name="right_shoulder_pitch_joint" pos="0 0 0" axis="0 1 0" range="-3.0892 2.6704"          armature=".025" />
              <geom type="mesh" contype="0" conaffinity="0" group="1" density="0" rgba="0.7 0.7 0.7 1" mesh="right_shoulder_pitch_link"/>
              <geom size="0.03 0.025" pos="0 -0.04 -0.01" quat="0.707107 0 0.707107 0" type="cylinder" rgba="0.7 0.7 0.7 1"/>
              <body name="right_shoulder_roll_link" pos="0 -0.038 -0.013831" quat="0.990268 0.139172 0 0">
                <inertial pos="-0.000227 -0.00727 -0.063243" quat="0.712604 -0.00710317 -0.0196223 0.701256" mass="0.643" diaginertia="0.000691311 0.000618011 0.000388977"/>
                <joint  name="right_shoulder_roll_joint" pos="0 0 0" axis="1 0 0" range="-2.2515 1.5882"        armature=".025" />
                <geom type="mesh" contype="0" conaffinity="0" group="1" density="0" rgba="0.7 0.7 0.7 1" mesh="right_shoulder_roll_link"/>
                <geom size="0.03 0.015" pos="-0.004 -0.006 -0.053" type="cylinder" rgba="0.7 0.7 0.7 1"/>
                <body name="right_shoulder_yaw_link" pos="0 -0.00624 -0.1032">
                  <inertial pos="0.010773 0.002949 -0.072009" quat="0.687134 -0.0679942 -0.0964829 0.716879" mass="0.734" diaginertia="0.00106187 0.00103217 0.000400661"/>
                  <joint  name="right_shoulder_yaw_joint" pos="0 0 0" axis="0 0 1" range="-2.618 2.618"         armature=".025" />
                  <geom type="mesh" contype="0" conaffinity="0" group="1" density="0" rgba="0.7 0.7 0.7 1" mesh="right_shoulder_yaw_link"/>
                  <geom type="mesh" rgba="0.7 0.7 0.7 1" mesh="right_shoulder_yaw_link"/>
                  <body name="right_elbow_link" pos="0.015783 0 -0.080518">
                    <inertial pos="0.134675 -0.00265598 -0.0101165" quat="0.485754 0.50107 0.498203 0.514554" mass="1.42407" diaginertia="0.00848486 0.00842107 0.000653284"/>
                    <joint    name="right_elbow_joint" pos="0 0 0" axis="0 1 0" range="-1.0472 2.0944"        armature=".025" />
                    <geom type="mesh" contype="0" conaffinity="0" group="1" density="0" rgba="0.7 0.7 0.7 1" mesh="right_elbow_link"/>
                    <geom type="mesh" rgba="0.7 0.7 0.7 1" mesh="right_elbow_link"/>
                    <geom pos="0.1 -0.00188791 -0.01" type="mesh" contype="0" conaffinity="0" group="1" density="0" rgba="0.7 0.7 0.7 1" mesh="right_wrist_roll_link"/>
                    <geom pos="0.1 -0.00188791 -0.01" type="mesh" rgba="0.7 0.7 0.7 1" mesh="right_wrist_roll_link"/>
                    <geom pos="0.138 -0.00188791 -0.01" type="mesh" contype="0" conaffinity="0" group="1" density="0" rgba="0.7 0.7 0.7 1" mesh="right_wrist_pitch_link"/>
                    <geom pos="0.138 -0.00188791 -0.01" type="mesh" rgba="0.7 0.7 0.7 1" mesh="right_wrist_pitch_link"/>
                    <geom pos="0.184 -0.00188791 -0.01" type="mesh" contype="0" conaffinity="0" group="1" density="0" rgba="0.7 0.7 0.7 1" mesh="right_wrist_yaw_link"/>
                    <geom pos="0.184 -0.00188791 -0.01" type="mesh" rgba="0.7 0.7 0.7 1" mesh="right_wrist_yaw_link"/>
                    <geom pos="0.2255 -0.00488791 -0.01" type="mesh" contype="0" conaffinity="0" group="1" density="0" rgba="0.7 0.7 0.7 1" mesh="right_rubber_hand"/>
                    <geom pos="0.2255 -0.00488791 -0.01" type="mesh" rgba="0.7 0.7 0.7 1" mesh="right_rubber_hand"/>
                    <body name="right_hand_link" pos="0.25 0 0">
                      <!-- <inertial pos="0.0536131 0.00295905 0.00215413" quat="0.464597 0.435405 0.552264 0.538123" mass="0.17" diaginertia="0.000288486 0.000218824 9.39911e-05"/>
                       -->
                      <geom type="sphere"  size="0.035" contype="0" conaffinity="0" group="1" density="0" rgba="0 0 0.7 1"/>
                    </body>
                  </body>
                </body>
              </body> 
            </body>
            <body name="head_link_o" pos="0 0 0.42">
              <!-- <inertial pos="0.0536131 0.00295905 0.00215413" quat="0.464597 0.435405 0.552264 0.538123" mass="0.17" diaginertia="0.000288486 0.000218824 9.39911e-05"/>
              <joint name="head_o_joint" pos="0 0 0" axis="1 0 0"/> -->
              <geom type="sphere" size="0.035" contype="0" conaffinity="0" group="1" density="0" rgba="0 0 0.7 1"/> 
            </body>
          </body>
        </body>
      </body>
    </body>
  </worldbody>
<!--   
  <actuator>
    <motor name="left_hip_pitch_joint"     gear='75' joint="left_hip_pitch_joint" />
    <motor name="left_hip_roll_joint"    gear='75'  joint="left_hip_roll_joint"  />
    <motor name="left_hip_yaw_joint"     gear='75' joint="left_hip_yaw_joint"  />
    <motor name="left_knee_joint"    gear='118'  joint="left_knee_joint"   />
    <motor name="left_ankle_pitch_joint"     gear='43' joint="left_ankle_pitch_joint"  />
    <motor name="left_ankle_roll_joint"    gear='43'  joint="left_ankle_roll_joint"   />
    <motor name="right_hip_pitch_joint"    gear='75'  joint="right_hip_pitch_joint"  />
    <motor name="right_hip_roll_joint"    gear='75'  joint="right_hip_roll_joint"   />
    <motor name="right_hip_yaw_joint"    gear='75'  joint="right_hip_yaw_joint"    />
    <motor name="right_knee_joint"    gear='118'  joint="right_knee_joint"   />
    <motor name="right_ankle_pitch_joint"     gear='43' joint="right_ankle_pitch_joint"  />
    <motor name="right_ankle_roll_joint"    gear='43'  joint="right_ankle_roll_joint"  />
    <motor name="waist_yaw_joint"    gear='75'  joint="waist_yaw_joint"  />
    <motor name="waist_roll_joint"    gear='43'  joint="waist_roll_joint"  />
    <motor name="waist_pitch_joint"    gear='43'  joint="waist_pitch_joint"   />
    <motor name="left_shoulder_pitch_joint"    gear='21'  joint="left_shoulder_pitch_joint"   />
    <motor name="left_shoulder_roll_joint"    gear='21'  joint="left_shoulder_roll_joint"   />
    <motor name="left_shoulder_yaw_joint"    gear='21'  joint="left_shoulder_yaw_joint"   />
    <motor name="left_elbow_joint"    gear='21'  joint="left_elbow_joint"   />
    <motor name="right_shoulder_pitch_joint"    gear='21'  joint="right_shoulder_pitch_joint"   />
    <motor name="right_shoulder_roll_joint"    gear='21'  joint="right_shoulder_roll_joint"   />
    <motor name="right_shoulder_yaw_joint"     gear='21' joint="right_shoulder_yaw_joint"   />
    <motor name="right_elbow_joint"    gear='21'  joint="right_elbow_joint"   />
  </actuator>
  -->


  <actuator>
    <motor name="left_hip_pitch_joint"     gear='1' joint="left_hip_pitch_joint"  ctrlrange="-74.8 74.8"  />
    <motor name="left_hip_roll_joint"    gear='1'  joint="left_hip_roll_joint"  ctrlrange="-74.8 74.8"  />
    <motor name="left_hip_yaw_joint"     gear='1' joint="left_hip_yaw_joint"  ctrlrange="-74.8 74.8"  />
    <motor name="left_knee_joint"    gear='1'  joint="left_knee_joint"  ctrlrange="-118.15 118.15"  />
    <motor name="left_ankle_pitch_joint"     gear='1' joint="left_ankle_pitch_joint"  ctrlrange="-42.5 42.5"  />
    <motor name="left_ankle_roll_joint"    gear='1'  joint="left_ankle_roll_joint"  ctrlrange="-42.5 42.5"  />
    <motor name="right_hip_pitch_joint"    gear='1'  joint="right_hip_pitch_joint"  ctrlrange="-74.8 74.8"  />
    <motor name="right_hip_roll_joint"    gear='1'  joint="right_hip_roll_joint"  ctrlrange="-74.8 74.8"  />
    <motor name="right_hip_yaw_joint"    gear='1'  joint="right_hip_yaw_joint"  ctrlrange="-74.8 74.8"  />
    <motor name="right_knee_joint"    gear='1'  joint="right_knee_joint"  ctrlrange="-118.15 118.15"  />
    <motor name="right_ankle_pitch_joint"     gear='1' joint="right_ankle_pitch_joint"  ctrlrange="-42.5 42.5"  />
    <motor name="right_ankle_roll_joint"    gear='1'  joint="right_ankle_roll_joint"  ctrlrange="-42.5 42.5"  />
    <motor name="waist_yaw_joint"    gear='1'  joint="waist_yaw_joint"  ctrlrange="-74.8 74.8"  />
    <motor name="waist_roll_joint"    gear='1'  joint="waist_roll_joint"  ctrlrange="-42.5 42.5"  />
    <motor name="waist_pitch_joint"    gear='1'  joint="waist_pitch_joint"  ctrlrange="-42.5 42.5"  />
    <motor name="left_shoulder_pitch_joint"    gear='1'  joint="left_shoulder_pitch_joint"  ctrlrange="-21.25 21.25"  />
    <motor name="left_shoulder_roll_joint"    gear='1'  joint="left_shoulder_roll_joint"  ctrlrange="-21.25 21.25"  />
    <motor name="left_shoulder_yaw_joint"    gear='1'  joint="left_shoulder_yaw_joint"  ctrlrange="-21.25 21.25"  />
    <motor name="left_elbow_joint"    gear='1'  joint="left_elbow_joint"  ctrlrange="-21.25 21.25"  />
    <motor name="right_shoulder_pitch_joint"    gear='1'  joint="right_shoulder_pitch_joint"  ctrlrange="-21.25 21.25"  />
    <motor name="right_shoulder_roll_joint"    gear='1'  joint="right_shoulder_roll_joint"  ctrlrange="-21.25 21.25"  />
    <motor name="right_shoulder_yaw_joint"     gear='1' joint="right_shoulder_yaw_joint"  ctrlrange="-21.25 21.25"  />
    <motor name="right_elbow_joint"    gear='1'  joint="right_elbow_joint"  ctrlrange="-21.25 21.25"  />
  </actuator>
 

  <sensor>
    <subtreelinvel name="pelvis_subtreelinvel" body="pelvis"/>
    <accelerometer name="root_accel"    site="root"/>
    <velocimeter name="root_vel"        site="root"/>
    <gyro name="root_gyro"              site="root"/>
  </sensor>
   <statistic center="1.0 0.7 1.0" extent="0.8"/>
  <visual>
    <headlight diffuse="0.6 0.6 0.6" ambient="0.1 0.1 0.1" specular="0.9 0.9 0.9"/>
    <rgba haze="0.15 0.25 0.35 1"/>
    <global azimuth="-140" elevation="-20"/>
  </visual>
  <asset>
    <texture type="skybox" builtin="flat" rgb1="0 0 0" rgb2="0 0 0" width="512" height="3072"/>
    <texture type="2d" name="groundplane" builtin="checker" mark="edge" rgb1="0.2 0.3 0.4" rgb2="0.1 0.2 0.3" markrgb="0.8 0.8 0.8" width="300" height="300"/>
    <material name="groundplane" texture="groundplane" texuniform="true" texrepeat="5 5" reflectance="0.2"/>
  </asset>
 
  <option>
  <flag contact="enable"/>  
  </option>

  <worldbody>
    <light pos="1 0 3.5" dir="0 0 -1" directional="true"/>
    <geom name="floor" size="0 0 0.05" type="plane" material="groundplane" friction="1.0 0.005 0.0001"/>             
  </worldbody>
</mujoco>